Workbook

Sheet Lisez-moi
B2: Parcoursup 2025 en Île-de-France
B3: Où la concurrence à l'entrée de l'enseignement supérieur est-elle la plus forte ?
B5: Auteur | C5: [NOM Prénom] — [N° étudiant]
B6: Formation | C6: [Filière], Université Paris Nanterre — année universitaire 2026-2027
B7: Cadre | C7: EC Compétences numériques : Machines et Logiciels — Séance 5, projet personnel
B9: Problématique
B10: Question 1 | C10: En Île-de-France, dans quelles filières le nombre de candidatures par place offerte est-il le plus élevé ?
B11: Question 2 | C11: Cette tension est-elle la même à Paris, en petite couronne et en grande couronne ?
B12: Indicateur | C12: Candidatures par place = nombre de candidats ayant confirmé un vœu dans la formation ÷ capacité d'accueil de la formation.
B14: Source des données (données ouvertes)
B15: Jeu de données | C15: Parcoursup 2025 — vœux de poursuite d'études et de réorientation dans l'enseignement supérieur et réponses des établissements
B16: Producteur | C16: Ministère chargé de l'Enseignement supérieur et de la Recherche — SIES (traitement des données Parcoursup)
B17: Adresse | C17: https://data.enseignementsup-recherche.gouv.fr/explore/dataset/fr-esr-parcoursup/
B18: Licence | C18: Licence Ouverte v2.0 (Etalab) — réutilisation libre avec mention de la source
B19: Version | C19: Jeu mis à jour le 9 mars 2026 ; téléchargé le 12 octobre 2026 au format CSV
B20: Périmètre retenu | C20: Filtre Région = Île-de-France : 2 691 formations sur 14 252 (hors apprentissage), 8 départements.
B21: Colonnes retenues | C21: 9 colonnes sur les 118 du fichier d'origine (voir ci-dessous).
B22: Nettoyage | C22: Libellés de filière harmonisés (Licence_Las → Licence L.AS ; Ecole d'Ingénieur → École d'ingénieur ; Ecole de Commerce → École de commerce) et sélectivité abrégée (Sélective / Non sélective). Aucune valeur numérique modifiée.
B24: Feuilles du classeur
B25: Données | C25: Les 2 691 formations. En-têtes bleus : colonnes d'origine. En-têtes orange : colonnes calculées par formule. Tri à deux niveaux (Filière, puis Candidatures par place décroissant) et filtres automatiques.
B26: Paramètres | C26: Table départements → zones (utilisée par RECHERCHEV) et seuils des niveaux de tension (utilisés par les SI imbriqués).
B27: Synthèse | C27: Tableau de synthèse par filière et par zone, calculé par formules (NB.SI, SOMME.SI, SOMME.SI.ENS), et graphique.
B28: TCD | C28: Tableaux croisés dynamiques : par filière, puis filière × zone, avec un champ calculé « candidatures par place ».
B29: Sous-totaux | C29: Liste triée par filière avec sous-totaux automatiques (Données > Sous-total) des places, candidatures et admis.
B30: Zoom Paris Nanterre | C30: Extraction par filtre avancé des formations de mon université, triées de la plus demandée à la moins demandée.
B32: Colonnes de la feuille Données
B33: Établissement | C33: Nom de l'établissement qui porte la formation | D33: origine : g_ea_lib_vx
B34: Code dép. / Département | C34: Département de l'établissement | D34: origine : dep, dep_lib
B35: Filière | C35: Type de formation très agrégé (Licence, BTS, BUT, CPGE, PASS…) | D35: origine : fili
B36: Formation | C36: Intitulé de la formation | D36: origine : lib_for_voe_ins
B37: Sélectivité | C37: Formation sélective ou non sélective | D37: origine : select_form
B38: Places | C38: Capacité de l'établissement pour la formation | D38: origine : capa_fin
B39: Candidatures | C39: Effectif total des candidats pour la formation | D39: origine : voe_tot
B40: Admis | C40: Candidats ayant accepté la proposition de l'établissement | D40: origine : acc_tot
B41: Zone | C41: Paris, Petite couronne ou Grande couronne | D41: calculée : RECHERCHEV
B42: Candidatures par place | C42: Candidatures ÷ Places | D42: calculée : SIERREUR
B43: Taux de remplissage | C43: Admis ÷ Places | D43: calculée : SIERREUR
B44: Niveau de tension | C44: Faible, Modérée, Forte ou Très forte selon les seuils | D44: calculée : SI imbriqués
B46: Limite de l'indicateur
B47: À garder en tête | C47: Un même candidat formule plusieurs vœux : les candidatures s'additionnent d'une formation à l'autre. Le ratio mesure donc l'attractivité d'une formation par rapport à sa capacité, pas la probabilité individuelle d'être admis.

Sheet Données
A1: Établissement | B1: Code dép. | C1: Département | D1: Filière | E1: Formation | F1: Sélectivité | G1: Places | H1: Candidatures | I1: Admis | J1: Zone | K1: Candidatures par place | L1: Taux de remplissage | M1: Niveau de tension
A2: ESAA Boulle | B2: 75 | C2: Paris | D2: Autre formation | E2: DN MADE - Espace - Spécialité : Architecture intérieure | F2: Sélective | G2: 15 | H2: 3723 | I2: 15 | J2: =VLOOKUP(B2,Paramètres!$A$4:$C$11,3,FALSE) -> Paris | K2: =IFERROR(H2/G2,"") -> 248.2 | L2: =IFERROR(I2/G2,"") -> 1 | M2: =IF(K2>=Paramètres!$F$6,"Très forte",IF(K2>=Paramètres!$F$5,"Forte",IF(K2>=Paramètres!$F$4,"Modérée","Faible"))) -> Très forte
A3: ECOLE NATIONALE SUPERIEURE A.A-MET.D'ART. | B3: 75 | C3: Paris | D3: Autre formation | E3: DN MADE - Espace - Spécialité : Architecture, habitat, mobilier et environnement | F3: Sélective | G3: 15 | H3: 3201 | I3: 16 | J3: =VLOOKUP(B3,Paramètres!$A$4:$C$11,3,FALSE) -> Paris | K3: =IFERROR(H3/G3,"") -> 213.4 | L3: =IFERROR(I3/G3,"") -> 1.0666667 | M3: =IF(K3>=Paramètres!$F$6,"Très forte",IF(K3>=Paramètres!$F$5,"Forte",IF(K3>=Paramètres!$F$4,"Modérée","Faible"))) -> Très forte
A4: Lycée Estienne Esaig | B4: 75 | C4: Paris | D4: Autre formation | E4: DN MADE - Animation - Spécialité : Cinéma d'Animation 2D | F4: Sélective | G4: 12 | H4: 2487 | I4: 12 | J4: =VLOOKUP(B4,Paramètres!$A$4:$C$11,3,FALSE) -> Paris | K4: =IFERROR(H4/G4,"") -> 207.25 | L4: =IFERROR(I4/G4,"") -> 1 | M4: =IF(K4>=Paramètres!$F$6,"Très forte",IF(K4>=Paramètres!$F$5,"Forte",IF(K4>=Paramètres!$F$4,"Modérée","Faible"))) -> Très forte
A5: Lycée Estienne Esaig | B5: 75 | C5: Paris | D5: Autre formation | E5: DN MADE - Graphisme - Spécialité : Designer graphique | F5: Sélective | G5: 15 | H5: 2696 | I5: 15 | J5: =VLOOKUP(B5,Paramètres!$A$4:$C$11,3,FALSE) -> Paris | K5: =IFERROR(H5/G5,"") -> 179.73333 | L5: =IFERROR(I5/G5,"") -> 1 | M5: =IF(K5>=Paramètres!$F$6,"Très forte",IF(K5>=Paramètres!$F$5,"Forte",IF(K5>=Paramètres!$F$4,"Modérée","Faible"))) -> Très forte
A6: Esaa Duperré | B6: 75 | C6: Paris | D6: Autre formation | E6: DN MADE - Mode - Spécialité : Stylisme, image et médiatisation | F6: Sélective | G6: 12 | H6: 2134 | I6: 12 | J6: =VLOOKUP(B6,Paramètres!$A$4:$C$11,3,FALSE) -> Paris | K6: =IFERROR(H6/G6,"") -> 177.83333 | L6: =IFERROR(I6/G6,"") -> 1 | M6: =IF(K6>=Paramètres!$F$6,"Très forte",IF(K6>=Paramètres!$F$5,"Forte",IF(K6>=Paramètres!$F$4,"Modérée","Faible"))) -> Très forte
A7: ECOLE NATIONALE SUPERIEURE A.A-MET.D'ART. | B7: 75 | C7: Paris | D7: Autre formation | E7: DN MADE - Graphisme - Spécialité : Identité visuelle et stratégie de communication | F7: Sélective | G7: 15 | H7: 2277 | I7: 16 | J7: =VLOOKUP(B7,Paramètres!$A$4:$C$11,3,FALSE) -> Paris | K7: =IFERROR(H7/G7,"") -> 151.8 | L7: =IFERROR(I7/G7,"") -> 1.0666667 | M7: =IF(K7>=Paramètres!$F$6,"Très forte",IF(K7>=Paramètres!$F$5,"Forte",IF(K7>=Paramètres!$F$4,"Modérée","Faible"))) -> Très forte
A8: ESAA Boulle | B8: 75 | C8: Paris | D8: Autre formation | E8: DN MADE - Ornement - Spécialité : Art et technique du bijou (Créateur-concepteur - ornement et objet d’exception) | F8: Sélective | G8: 5 | H8: 742 | I8: 5 | J8: =VLOOKUP(B8,Paramètres!$A$4:$C$11,3,FALSE) -> Paris | K8: =IFERROR(H8/G8,"") -> 148.4 | L8: =IFERROR(I8/G8,"") -> 1 | M8: =IF(K8>=Paramètres!$F$6,"Très forte",IF(K8>=Paramètres!$F$5,"Forte",IF(K8>=Paramètres!$F$4,"Modérée","Faible"))) -> Très forte
A9: Lycée Estienne Esaig | B9: 75 | C9: Paris | D9: Autre formation | E9: DN MADE - Animation - Spécialité : Cinéma d'animation 3D | F9: Sélective | G9: 12 | H9: 1731 | I9: 12 | J9: =VLOOKUP(B9,Paramètres!$A$4:$C$11,3,FALSE) -> Paris | K9: =IFERROR(H9/G9,"") -> 144.25 | L9: =IFERROR(I9/G9,"") -> 1 | M9: =IF(K9>=Paramètres!$F$6,"Très forte",IF(K9>=Paramètres!$F$5,"Forte",IF(K9>=Paramètres!$F$4,"Modérée","Faible"))) -> Très forte
A10: Lycée Auguste Renoir | B10: 75 | C10: Paris | D10: Autre formation | E10: DN MADE - Graphisme - Spécialité : Image et narration | F10: Sélective | G10: 12 | H10: 1729 | I10: 12 | J10: =VLOOKUP(B10,Paramètres!$A$4:$C$11,3,FALSE) -> Paris | K10: =IFERROR(H10/G10,"") -> 144.08333 | L10: =IFERROR(I10/G10,"") -> 1 | M10: =IF(K10>=Paramètres!$F$6,"Très forte",IF(K10>=Paramètres!$F$5,"Forte",IF(K10>=Paramètres!$F$4,"Modérée","Faible"))) -> Très forte
A11: Institut d'études politiques de Paris - Sciences Po | B11: 75 | C11: Paris | D11: Autre formation | E11: Sciences Po / Instituts d'études politiques - Sciences Humaines et Sociales - Grade Licence - Double diplôme Sciences Po-LUISS | F11: Sélective | G11: 1 | H11: 143 | I11: 1 | J11: =VLOOKUP(B11,Paramètres!$A$4:$C$11,3,FALSE) -> Paris | K11: =IFERROR(H11/G11,"") -> 143 | L11: =IFERROR(I11/G11,"") -> 1 | M11: =IF(K11>=Paramètres!$F$6,"Très forte",IF(K11>=Paramètres!$F$5,"Forte",IF(K11>=Paramètres!$F$4,"Modérée","Faible"))) -> Très forte
A12: ECOLE NATIONALE SUPERIEURE A.A-MET.D'ART. | B12: 75 | C12: Paris | D12: Autre formation | E12: DN MADE - Espace - Spécialité : ARCHITECTURE, ESPACES PUBLICS ET CONTEXTES URBAINS | F12: Sélective | G12: 15 | H12: 2098 | I12: 15 | J12: =VLOOKUP(B12,Paramètres!$A$4:$C$11,3,FALSE) -> Paris | K12: =IFERROR(H12/G12,"") -> 139.86667 | L12: =IFERROR(I12/G12,"") -> 1 | M12: =IF(K12>=Paramètres!$F$6,"Très forte",IF(K12>=Paramètres!$F$5,"Forte",IF(K12>=Paramètres!$F$4,"Modérée","Faible"))) -> Très forte
A13: Esaa Duperré | B13: 75 | C13: Paris | D13: Autre formation | E13: DN MADE - Mode - Spécialité : Textile, Mode, Recherche et Développement | F13: Sélective | G13: 12 | H13: 1609 | I13: 12 | J13: =VLOOKUP(B13,Paramètres!$A$4:$C$11,3,FALSE) -> Paris | K13: =IFERROR(H13/G13,"") -> 134.08333 | L13: =IFERROR(I13/G13,"") -> 1 | M13: =IF(K13>=Paramètres!$F$6,"Très forte",IF(K13>=Paramètres!$F$5,"Forte",IF(K13>=Paramètres!$F$4,"Modérée","Faible"))) -> Très forte
... A2692: Sorbonne université | B2692: 75 | C2692: Paris | D2692: PASS | E2692: Licence - Parcours d'Accès Spécifique Santé (PASS) | F2692: Non sélective | G2692: 1200 | H2692: 15253 | I2692: 1197 | J2692: =VLOOKUP(B2692,Paramètres!$A$4:$C$11,3,FALSE) -> Paris | K2692: =IFERROR(H2692/G2692,"") -> 12.710833 | L2692: =IFERROR(I2692/G2692,"") -> 0.9975 | M2692: =IF(K2692>=Paramètres!$F$6,"Très forte",IF(K2692>=Paramètres!$F$5,"Forte",IF(K2692>=Paramètres!$F$4,"Modérée","Faible"))) -> Modérée

Sheet Paramètres
A1: Tables de référence utilisées par les formules de la feuille Données
A3: Code dép. | B3: Département | C3: Zone | E3: Niveau de tension | F3: Seuil minimal (candidatures par place)
A4: 75 | B4: Paris | C4: Paris | E4: Modérée | F4: 10
A5: 77 | B5: Seine-et-Marne | C5: Grande couronne | E5: Forte | F5: 20
A6: 78 | B6: Yvelines | C6: Grande couronne | E6: Très forte | F6: 40
A7: 91 | B7: Essonne | C7: Grande couronne | E7: En dessous de 10 : « Faible ».
A8: 92 | B8: Hauts-de-Seine | C8: Petite couronne
A9: 93 | B9: Seine-Saint-Denis | C9: Petite couronne | E9: Seuils choisis d'après la répartition des 2 691 formations : environ un quart des formations dans chaque niveau.
A10: 94 | B10: Val-de-Marne | C10: Petite couronne
A11: 95 | B11: Val-d'Oise | C11: Grande couronne
A13: Utilisation : =RECHERCHEV(code dép. ; $A$4:$C$11 ; 3 ; FAUX) renvoie la zone.

Sheet Synthèse
A1: Tableau de synthèse — candidatures par place selon la filière (Île-de-France, Parcoursup 2025)
A2: Calculé par formules (NB.SI, SOMME.SI) à partir de la feuille Données. Trié de la filière la plus demandée à la moins demandée.
A4: Filière | B4: Formations | C4: Places | D4: Candidatures | E4: Admis | F4: Candidatures par place | G4: Taux de remplissage | H4: Part des places
A5: PASS | B5: =COUNTIF(Données!$D$2:$D$2692,$A5) -> 35 | C5: =SUMIF(Données!$D$2:$D$2692,$A5,Données!$G$2:$G$2692) -> 4621 | D5: =SUMIF(Données!$D$2:$D$2692,$A5,Données!$H$2:$H$2692) -> 374935 | E5: =SUMIF(Données!$D$2:$D$2692,$A5,Données!$I$2:$I$2692) -> 4581 | F5: =IFERROR(D5/C5,"") -> 81.1372 | G5: =IFERROR(E5/C5,"") -> 0.99134386 | H5: =C5/$C$16 -> 0.030157477
A6: IFSI | B6: =COUNTIF(Données!$D$2:$D$2692,$A6) -> 57 | C6: =SUMIF(Données!$D$2:$D$2692,$A6,Données!$G$2:$G$2692) -> 6238 | D6: =SUMIF(Données!$D$2:$D$2692,$A6,Données!$H$2:$H$2692) -> 364480 | E6: =SUMIF(Données!$D$2:$D$2692,$A6,Données!$I$2:$I$2692) -> 6117 | F6: =IFERROR(D6/C6,"") -> 58.428984 | G6: =IFERROR(E6/C6,"") -> 0.98060276 | H6: =C6/$C$16 -> 0.040710309
A7: BUT | B7: =COUNTIF(Données!$D$2:$D$2692,$A7) -> 113 | C7: =SUMIF(Données!$D$2:$D$2692,$A7,Données!$G$2:$G$2692) -> 8802 | D7: =SUMIF(Données!$D$2:$D$2692,$A7,Données!$H$2:$H$2692) -> 360253 | E7: =SUMIF(Données!$D$2:$D$2692,$A7,Données!$I$2:$I$2692) -> 8780 | F7: =IFERROR(D7/C7,"") -> 40.928539 | G7: =IFERROR(E7/C7,"") -> 0.99750057 | H7: =C7/$C$16 -> 0.057443434
A8: Licence L.AS | B8: =COUNTIF(Données!$D$2:$D$2692,$A8) -> 106 | C8: =SUMIF(Données!$D$2:$D$2692,$A8,Données!$G$2:$G$2692) -> 3628 | D8: =SUMIF(Données!$D$2:$D$2692,$A8,Données!$H$2:$H$2692) -> 147850 | E8: =SUMIF(Données!$D$2:$D$2692,$A8,Données!$I$2:$I$2692) -> 3601 | F8: =IFERROR(D8/C8,"") -> 40.752481 | G8: =IFERROR(E8/C8,"") -> 0.99255788 | H8: =C8/$C$16 -> 0.02367698
A9: CPGE | B9: =COUNTIF(Données!$D$2:$D$2692,$A9) -> 271 | C9: =SUMIF(Données!$D$2:$D$2692,$A9,Données!$G$2:$G$2692) -> 14049 | D9: =SUMIF(Données!$D$2:$D$2692,$A9,Données!$H$2:$H$2692) -> 542035 | E9: =SUMIF(Données!$D$2:$D$2692,$A9,Données!$I$2:$I$2692) -> 13274 | F9: =IFERROR(D9/C9,"") -> 38.58175 | G9: =IFERROR(E9/C9,"") -> 0.94483593 | H9: =C9/$C$16 -> 0.0916863
A10: BTS | B10: =COUNTIF(Données!$D$2:$D$2692,$A10) -> 727 | C10: =SUMIF(Données!$D$2:$D$2692,$A10,Données!$G$2:$G$2692) -> 23445 | D10: =SUMIF(Données!$D$2:$D$2692,$A10,Données!$H$2:$H$2692) -> 676730 | E10: =SUMIF(Données!$D$2:$D$2692,$A10,Données!$I$2:$I$2692) -> 20665 | F10: =IFERROR(D10/C10,"") -> 28.864577 | G10: =IFERROR(E10/C10,"") -> 0.88142461 | H10: =C10/$C$16 -> 0.15300628
A11: École d'ingénieur | B11: =COUNTIF(Données!$D$2:$D$2692,$A11) -> 126 | C11: =SUMIF(Données!$D$2:$D$2692,$A11,Données!$G$2:$G$2692) -> 6601 | D11: =SUMIF(Données!$D$2:$D$2692,$A11,Données!$H$2:$H$2692) -> 173957 | E11: =SUMIF(Données!$D$2:$D$2692,$A11,Données!$I$2:$I$2692) -> 5785 | F11: =IFERROR(D11/C11,"") -> 26.353128 | G11: =IFERROR(E11/C11,"") -> 0.87638237 | H11: =C11/$C$16 -> 0.043079313
A12: École de commerce | B12: =COUNTIF(Données!$D$2:$D$2692,$A12) -> 96 | C12: =SUMIF(Données!$D$2:$D$2692,$A12,Données!$G$2:$G$2692) -> 8365 | D12: =SUMIF(Données!$D$2:$D$2692,$A12,Données!$H$2:$H$2692) -> 174284 | E12: =SUMIF(Données!$D$2:$D$2692,$A12,Données!$I$2:$I$2692) -> 5422 | F12: =IFERROR(D12/C12,"") -> 20.834907 | G12: =IFERROR(E12/C12,"") -> 0.64817693 | H12: =C12/$C$16 -> 0.054591494
A13: Autre formation | B13: =COUNTIF(Données!$D$2:$D$2692,$A13) -> 402 | C13: =SUMIF(Données!$D$2:$D$2692,$A13,Données!$G$2:$G$2692) -> 13567 | D13: =SUMIF(Données!$D$2:$D$2692,$A13,Données!$H$2:$H$2692) -> 274478 | E13: =SUMIF(Données!$D$2:$D$2692,$A13,Données!$I$2:$I$2692) -> 11748 | F13: =IFERROR(D13/C13,"") -> 20.231297 | G13: =IFERROR(E13/C13,"") -> 0.86592467 | H13: =C13/$C$16 -> 0.088540681
A14: Licence | B14: =COUNTIF(Données!$D$2:$D$2692,$A14) -> 721 | C14: =SUMIF(Données!$D$2:$D$2692,$A14,Données!$G$2:$G$2692) -> 62105 | D14: =SUMIF(Données!$D$2:$D$2692,$A14,Données!$H$2:$H$2692) -> 1089458 | E14: =SUMIF(Données!$D$2:$D$2692,$A14,Données!$I$2:$I$2692) -> 61103 | F14: =IFERROR(D14/C14,"") -> 17.542195 | G14: =IFERROR(E14/C14,"") -> 0.98386603 | H14: =C14/$C$16 -> 0.40530839
A15: EFTS | B15: =COUNTIF(Données!$D$2:$D$2692,$A15) -> 37 | C15: =SUMIF(Données!$D$2:$D$2692,$A15,Données!$G$2:$G$2692) -> 1808 | D15: =SUMIF(Données!$D$2:$D$2692,$A15,Données!$H$2:$H$2692) -> 18782 | E15: =SUMIF(Données!$D$2:$D$2692,$A15,Données!$I$2:$I$2692) -> 1521 | F15: =IFERROR(D15/C15,"") -> 10.388274 | G15: =IFERROR(E15/C15,"") -> 0.84126106 | H15: =C15/$C$16 -> 0.011799333
A16: Île-de-France | B16: =SUM(B5:B15) -> 2691 | C16: =SUM(C5:C15) -> 153229 | D16: =SUM(D5:D15) -> 4197242 | E16: =SUM(E5:E15) -> 142597 | F16: =D16/C16 -> 27.391956 | G16: =E16/C16 -> 0.93061366 | H16: =SUM(H5:H15) -> 1
A18: Par zone géographique
A19: Zone | B19: Formations | C19: Places | D19: Candidatures | E19: Admis | F19: Candidatures par place
A20: Paris | B20: =COUNTIF(Données!$J$2:$J$2692,$A20) -> 1034 | C20: =SUMIF(Données!$J$2:$J$2692,$A20,Données!$G$2:$G$2692) -> 63771 | D20: =SUMIF(Données!$J$2:$J$2692,$A20,Données!$H$2:$H$2692) -> 1869466 | E20: =SUMIF(Données!$J$2:$J$2692,$A20,Données!$I$2:$I$2692) -> 60068 | F20: =IFERROR(D20/C20,"") -> 29.3153
A21: Petite couronne | B21: =COUNTIF(Données!$J$2:$J$2692,$A21) -> 870 | C21: =SUMIF(Données!$J$2:$J$2692,$A21,Données!$G$2:$G$2692) -> 50723 | D21: =SUMIF(Données!$J$2:$J$2692,$A21,Données!$H$2:$H$2692) -> 1416275 | E21: =SUMIF(Données!$J$2:$J$2692,$A21,Données!$I$2:$I$2692) -> 46870 | F21: =IFERROR(D21/C21,"") -> 27.921751
A22: Grande couronne | B22: =COUNTIF(Données!$J$2:$J$2692,$A22) -> 787 | C22: =SUMIF(Données!$J$2:$J$2692,$A22,Données!$G$2:$G$2692) -> 38735 | D22: =SUMIF(Données!$J$2:$J$2692,$A22,Données!$H$2:$H$2692) -> 911501 | E22: =SUMIF(Données!$J$2:$J$2692,$A22,Données!$I$2:$I$2692) -> 35659 | F22: =IFERROR(D22/C22,"") -> 23.531716
A25: Repères : mon université
A26: Périmètre | B26: Formations | C26: Places | D26: Candidatures | E26: Admis | F26: Candidatures par place | J26: En orange : la licence, qui offre à elle seule 4 places sur 10.
A27: Université Paris Nanterre | B27: =COUNTIF(Données!$A$2:$A$2692,"*Paris Nanterre*") -> 87 | C27: =SUMIF(Données!$A$2:$A$2692,"*Paris Nanterre*",Données!$G$2:$G$2692) -> 7037 | D27: =SUMIF(Données!$A$2:$A$2692,"*Paris Nanterre*",Données!$H$2:$H$2692) -> 139434 | E27: =SUMIF(Données!$A$2:$A$2692,"*Paris Nanterre*",Données!$I$2:$I$2692) -> 6947 | F27: =IFERROR(D27/C27,"") -> 19.81441
A28: dont licence MIASHS | B28: =COUNTIFS(Données!$A$2:$A$2692,"Université Paris Nanterre",Données!$E$2:$E$2692,"Licence - Mathématiques et informatique appliquées aux sciences humaines et sociales") -> 1 | C28: =SUMIFS(Données!$G$2:$G$2692,Données!$A$2:$A$2692,"Université Paris Nanterre",Données!$E$2:$E$2692,"Licence - Mathématiques et informatique appliquées aux sciences humaines et sociales") -> 70 | D28: =SUMIFS(Données!$H$2:$H$2692,Données!$A$2:$A$2692,"Université Paris Nanterre",Données!$E$2:$E$2692,"Licence - Mathématiques et informatique appliquées aux sciences humaines et sociales") -> 1342 | E28: =SUMIFS(Données!$I$2:$I$2692,Données!$A$2:$A$2692,"Université Paris Nanterre",Données!$E$2:$E$2692,"Licence - Mathématiques et informatique appliquées aux sciences humaines et sociales") -> 69 | F28: =IFERROR(D28/C28,"") -> 19.171429
A29: Les formations de l'IUT de Ville-d'Avray sont répertoriées sous un autre libellé d'établissement et ne sont pas comptées ici.

Sheet TCD
A1: Tableaux croisés dynamiques — source : feuille Données (2 691 formations)
A2: Champ calculé « Cand. par place » = Candidatures / Places (Analyse du tableau croisé dynamique > Champs, éléments et jeux > Champ calculé).
A3: TCD 1 — par filière, de la plus demandée à la moins demandée | H3: TCD 2 — filière × zone géographique
A4: Sélectivité | B4: (Tous)
A6: Filière | B6: Nb de formations | C6: Somme des places | D6: Somme des candidatures | E6: Cand. par place | H6: Candidatures par place | I6: Zone
A7: PASS | B7: 35 | C7: 4621 | D7: 374935 | E7: 81.1372 | H7: Filière | I7: Paris | J7: Petite couronne | K7: Grande couronne | L7: Total général
A8: IFSI | B8: 57 | C8: 6238 | D8: 364480 | E8: 58.428984 | H8: PASS | I8: 52.593478 | J8: 280.7662 | K8: 101.2543 | L8: 81.1372
A9: BUT | B9: 113 | C9: 8802 | D9: 360253 | E9: 40.928539 | H9: IFSI | I9: 75.690355 | J9: 56.485159 | K9: 49.744131 | L9: 58.428984
A10: Licence L.AS | B10: 106 | C10: 3628 | D10: 147850 | E10: 40.752481 | H10: BUT | I10: 49.64442 | J10: 50.675615 | K10: 28.930036 | L10: 40.928539
A11: CPGE | B11: 271 | C11: 14049 | D11: 542035 | E11: 38.58175 | H11: Licence L.AS | I11: 60.920593 | J11: 28.229319 | K11: 42.162587 | L11: 40.752481
A12: BTS | B12: 727 | C12: 23445 | D12: 676730 | E12: 28.864577 | H12: CPGE | I12: 48.080778 | J12: 29.815154 | K12: 26.240142 | L12: 38.58175
A13: École d'ingénieur | B13: 126 | C13: 6601 | D13: 173957 | E13: 26.353128 | H13: BTS | I13: 40.392686 | J13: 29.967854 | K13: 19.832285 | L13: 28.864577
A14: École de commerce | B14: 96 | C14: 8365 | D14: 174284 | E14: 20.834907 | H14: École d'ingénieur | I14: 32.481716 | J14: 22.551282 | K14: 29.805023 | L14: 26.353128
A15: Autre formation | B15: 402 | C15: 13567 | D15: 274478 | E15: 20.231297 | H15: École de commerce | I15: 18.820333 | J15: 22.471839 | K15: 20.98882 | L15: 20.834907
A16: Licence | B16: 721 | C16: 62105 | D16: 1089458 | E16: 17.542195 | H16: Autre formation | I16: 22.871482 | J16: 16.830992 | K16: 16.205071 | L16: 20.231297
A17: EFTS | B17: 37 | C17: 1808 | D17: 18782 | E17: 10.388274 | H17: Licence | I17: 18.925259 | J17: 17.681228 | K17: 14.011909 | L17: 17.542195
A18: Total général | B18: 2691 | C18: 153229 | D18: 4197242 | E18: 27.391956 | H18: EFTS | I18: 10.990099 | J18: 13.492537 | K18: 7.4113924 | L18: 10.388274
H19: Total général | I19: 29.3153 | J19: 27.921751 | K19: 23.531716 | L19: 27.391956

Sheet Sous-totaux
A1: Filière | B1: Zone | C1: Établissement | D1: Formation | E1: Places | F1: Candidatures | G1: Admis | H1: Candidatures par place
A2: Autre formation | B2: Paris | C2: ESAA Boulle | D2: DN MADE - Espace - Spécialité : Architecture intérieure | E2: 15 | F2: 3723 | G2: 15 | H2: =IFERROR(F2/E2,"") -> 248.2
A3: Autre formation | B3: Paris | C3: ECOLE NATIONALE SUPERIEURE A.A-MET.D'ART. | D3: DN MADE - Espace - Spécialité : Architecture, habitat, mobilier et environnement | E3: 15 | F3: 3201 | G3: 16 | H3: =IFERROR(F3/E3,"") -> 213.4
A4: Autre formation | B4: Paris | C4: Lycée Estienne Esaig | D4: DN MADE - Animation - Spécialité : Cinéma d'Animation 2D | E4: 12 | F4: 2487 | G4: 12 | H4: =IFERROR(F4/E4,"") -> 207.25
A5: Autre formation | B5: Paris | C5: Lycée Estienne Esaig | D5: DN MADE - Graphisme - Spécialité : Designer graphique | E5: 15 | F5: 2696 | G5: 15 | H5: =IFERROR(F5/E5,"") -> 179.73333
A6: Autre formation | B6: Paris | C6: Esaa Duperré | D6: DN MADE - Mode - Spécialité : Stylisme, image et médiatisation | E6: 12 | F6: 2134 | G6: 12 | H6: =IFERROR(F6/E6,"") -> 177.83333
A7: Autre formation | B7: Paris | C7: ECOLE NATIONALE SUPERIEURE A.A-MET.D'ART. | D7: DN MADE - Graphisme - Spécialité : Identité visuelle et stratégie de communication | E7: 15 | F7: 2277 | G7: 16 | H7: =IFERROR(F7/E7,"") -> 151.8
A8: Autre formation | B8: Paris | C8: ESAA Boulle | D8: DN MADE - Ornement - Spécialité : Art et technique du bijou (Créateur-concepteur - ornement et objet d’exception) | E8: 5 | F8: 742 | G8: 5 | H8: =IFERROR(F8/E8,"") -> 148.4
A9: Autre formation | B9: Paris | C9: Lycée Estienne Esaig | D9: DN MADE - Animation - Spécialité : Cinéma d'animation 3D | E9: 12 | F9: 1731 | G9: 12 | H9: =IFERROR(F9/E9,"") -> 144.25
A10: Autre formation | B10: Paris | C10: Lycée Auguste Renoir | D10: DN MADE - Graphisme - Spécialité : Image et narration | E10: 12 | F10: 1729 | G10: 12 | H10: =IFERROR(F10/E10,"") -> 144.08333
A11: Autre formation | B11: Paris | C11: Institut d'études politiques de Paris - Sciences Po | D11: Sciences Po / Instituts d'études politiques - Sciences Humaines et Sociales - Grade Licence - Double diplôme Sciences Po-LUISS | E11: 1 | F11: 143 | G11: 1 | H11: =IFERROR(F11/E11,"") -> 143
A12: Autre formation | B12: Paris | C12: ECOLE NATIONALE SUPERIEURE A.A-MET.D'ART. | D12: DN MADE - Espace - Spécialité : ARCHITECTURE, ESPACES PUBLICS ET CONTEXTES URBAINS | E12: 15 | F12: 2098 | G12: 15 | H12: =IFERROR(F12/E12,"") -> 139.86667
A13: Autre formation | B13: Paris | C13: Esaa Duperré | D13: DN MADE - Mode - Spécialité : Textile, Mode, Recherche et Développement | E13: 12 | F13: 1609 | G13: 12 | H13: =IFERROR(F13/E13,"") -> 134.08333
... A403: Autre formation | B403: Grande couronne | C403: Lycée LAVOISIER | D403: Certificat de Spécialisation - Techn. en énergies renouvelables opt. b énergie thermique | E403: 6 | F403: 1 | G403: 0 | H403: =IFERROR(F403/E403,"") -> 0.16666667
A404: Total Autre formation | E404: =SUBTOTAL(9,E2:E403) -> 13567 | F404: =SUBTOTAL(9,F2:F403) -> 274478 | G404: =SUBTOTAL(9,G2:G403) -> 11748 | H404: =IFERROR(F404/E404,"") -> 20.231297
A405: BTS | B405: Paris | C405: Lycée Edgar Quinet | D405: BTS - Services - Commerce International | E405: 24 | F405: 4955 | G405: 23 | H405: =IFERROR(F405/E405,"") -> 206.45833
A406: BTS | B406: Paris | C406: Lycée Jules SIEGFRIED | D406: BTS - Services - Commerce International | E406: 24 | F406: 4689 | G406: 24 | H406: =IFERROR(F406/E406,"") -> 195.375
A407: BTS | B407: Paris | C407: Ecole Nationale De Commerce | D407: BTS - Services - Commerce International | E407: 70 | F407: 11222 | G407: 69 | H407: =IFERROR(F407/E407,"") -> 160.31429
A408: BTS | B408: Paris | C408: Lycée Jean Lurcat | D408: BTS - Services - Négociation et digitalisation de la Relation Client | E408: 35 | F408: 5519 | G408: 35 | H408: =IFERROR(F408/E408,"") -> 157.68571
A409: BTS | B409: Paris | C409: Lycée Emile Dubois | D409: BTS - Services - Commerce International | E409: 35 | F409: 5326 | G409: 39 | H409: =IFERROR(F409/E409,"") -> 152.17143
A410: BTS | B410: Petite couronne | C410: Lycée Jacques Prevert | D410: BTS - Services - Métiers de l'audio-visuel opt : montage et post-production | E410: 12 | F410: 1725 | G410: 11 | H410: =IFERROR(F410/E410,"") -> 143.75
A411: BTS | B411: Petite couronne | C411: Lycée Jacques Prevert | D411: BTS - Services - Métiers de l'audio-visuel opt : métiers de l'image | E411: 12 | F411: 1697 | G411: 12 | H411: =IFERROR(F411/E411,"") -> 141.41667
A412: BTS | B412: Paris | C412: Lycée Sophie Germain | D412: BTS - Services - Communication | E412: 24 | F412: 3293 | G412: 20 | H412: =IFERROR(F412/E412,"") -> 137.20833
A413: BTS | B413: Petite couronne | C413: Lycée Suger | D413: BTS - Services - Métiers de l'audio-visuel opt : métiers de l'image | E413: 13 | F413: 1743 | G413: 13 | H413: =IFERROR(F413/E413,"") -> 134.07692
A414: BTS | B414: Paris | C414: Lycée professionnel Galilee | D414: BTS - Services - Prothésiste dentaire | E414: 15 | F414: 1977 | G414: 13 | H414: =IFERROR(F414/E414,"") -> 131.8
A415: BTS | B415: Paris | C415: Lycée Diderot | D415: BTS - Production - Cybersécurité, Informatique et réseaux, ELectronique - Option A : Informatique et réseaux | E415: 30 | F415: 3914 | G415: 30 | H415: =IFERROR(F415/E415,"") -> 130.46667
A416: BTS | B416: Paris | C416: Lycée Maurice Ravel | D416: BTS - Services - Commerce International | E416: 35 | F416: 4513 | G416: 33 | H416: =IFERROR(F416/E416,"") -> 128.94286
... A1131: BTS | B1131: Grande couronne | C1131: Lycée professionnel Agricole SULLY | D1131: BTS - Agricole - Agronomie et cultures durables | E1131: 42 | F1131: 54 | G1131: 15 | H1131: =IFERROR(F1131/E1131,"") -> 1.2857143
A1132: Total BTS | E1132: =SUBTOTAL(9,E405:E1131) -> 23445 | F1132: =SUBTOTAL(9,F405:F1131) -> 676730 | G1132: =SUBTOTAL(9,G405:G1131) -> 20665 | H1132: =IFERROR(F1132/E1132,"") -> 28.864577
A1133: BUT | B1133: Petite couronne | C1133: I.U.T de Ville d'Avray - Antenne de Nanterre | D1133: BUT - Gestion des entreprises et des administrations | E1133: 50 | F1133: 6294 | G1133: 54 | H1133: =IFERROR(F1133/E1133,"") -> 125.88
A1134: BUT | B1134: Petite couronne | C1134: IUT de Créteil Vitry (Site de Vitry) - UPEC | D1134: BUT - Gestion des entreprises et des administrations | E1134: 90 | F1134: 9291 | G1134: 102 | H1134: =IFERROR(F1134/E1134,"") -> 103.23333
A1135: BUT | B1135: Petite couronne | C1135: I.U.T. de Bobigny - Université Sorbonne Paris Nord, Paris XIII (93) | D1135: BUT - Gestion des entreprises et des administrations | E1135: 112 | F1135: 11402 | G1135: 111 | H1135: =IFERROR(F1135/E1135,"") -> 101.80357
A1136: BUT | B1136: Grande couronne | C1136: I.U.T de Marne la Vallée | D1136: BUT - Informatique | E1136: 45 | F1136: 4558 | G1136: 45 | H1136: =IFERROR(F1136/E1136,"") -> 101.28889
A1137: BUT | B1137: Paris | C1137: IUT de Paris - Rives de Seine - Université Paris Cité | D1137: BUT - Information communication Parcours publicité | E1137: 28 | F1137: 2735 | G1137: 28 | H1137: =IFERROR(F1137/E1137,"") -> 97.678571
A1138: BUT | B1138: Petite couronne | C1138: I.U.T de Tremblay-en-France - Paris 8 | D1138: BUT - Gestion des entreprises et des administrations | E1138: 60 | F1138: 5702 | G1138: 57 | H1138: =IFERROR(F1138/E1138,"") -> 95.033333
A1139: BUT | B1139: Grande couronne | C1139: Antenne - Institut Universitaire de Technologie Juvisy sur Orge - Université d'Evry Val d'Essonne | D1139: BUT - Techniques de commercialisation | E1139: 39 | F1139: 3376 | G1139: 38 | H1139: =IFERROR(F1139/E1139,"") -> 86.564103
A1140: BUT | B1140: Petite couronne | C1140: I.U.T. de Bobigny - Université Sorbonne Paris Nord, Paris XIII (93) | D1140: BUT - Métiers du multimédia et de l'internet | E1140: 50 | F1140: 4230 | G1140: 52 | H1140: =IFERROR(F1140/E1140,"") -> 84.6
A1141: BUT | B1141: Petite couronne | C1141: I.U.T de Ville d'Avray - Antenne de Nanterre | D1141: BUT - Techniques de commercialisation | E1141: 84 | F1141: 7012 | G1141: 85 | H1141: =IFERROR(F1141/E1141,"") -> 83.47619
A1142: BUT | B1142: Petite couronne | C1142: I.U.T. de Bobigny - Université Sorbonne Paris Nord, Paris XIII (93) | D1142: BUT - Génie biologique parcours biologie médicale et biotechnologie | E1142: 28 | F1142: 2320 | G1142: 28 | H1142: =IFERROR(F1142/E1142,"") -> 82.857143
A1143: BUT | B1143: Petite couronne | C1143: I.U.T de Villetaneuse - Université Sorbonne Paris Nord | D1143: BUT - Gestion des entreprises et des administrations | E1143: 140 | F1143: 11529 | G1143: 139 | H1143: =IFERROR(F1143/E1143,"") -> 82.35
...

Sheet Zoom Paris Nanterre
A1: Zoom : les formations de l'Université Paris Nanterre, de la plus demandée à la moins demandée
A2: Obtenu par filtre avancé (Données > Avancé > Copier vers un autre emplacement) puis tri décroissant sur les candidatures par place.
A4: Zone de critères
A5: Établissement
A6: *Paris Nanterre* | B6: ← l'astérisque remplace n'importe quel texte : « contient Paris Nanterre »
A8: Établissement | B8: Filière | C8: Formation | D8: Places | E8: Candidatures | F8: Admis | G8: Candidatures par place | H8: Taux de remplissage | I8: Niveau de tension
A9: Université Paris Nanterre | B9: Licence L.AS | C9: Licence - Portail Psychologie | D9: 35 | E9: 5981 | F9: 35 | G9: 170.88571 | H9: 1 | I9: Très forte
A10: Université Paris Nanterre | B10: Licence | C10: Licence - Economie et gestion - Parcours Economie et gestion - cursus international intégré franco-allemand | D10: 20 | E10: 1752 | F10: 20 | G10: 87.6 | H10: 1 | I10: Très forte
A11: Université Paris Nanterre | B11: Licence L.AS | C11: Licence - Portail Sciences et Techniques des Activités Physiques et Sportives | D11: 35 | E11: 2902 | F11: 34 | G11: 82.914286 | H11: 0.97142857 | I11: Très forte
A12: Université Paris Nanterre | B12: Licence | C12: Double licence - Langues, littératures et civilisations étrangères et régionales / Langues, littératures et civilisations étrangères et régionales - Double Licence mention Langues, littératures et civilisations étrangères et régionales (LLCER) [Anglais] - mention LLCER [Espagnol] | D12: 10 | E12: 811 | F12: 10 | G12: 81.1 | H12: 1 | I12: Très forte
A13: Université Paris Nanterre | B13: Licence | C13: Double licence - Economie et gestion / Mathématiques et informatique appliquées aux sciences humaines et sociales - Double Licence mention Economie et gestion [Gestion] - mention MIASHS [Informatique] | D13: 35 | E13: 2586 | F13: 34 | G13: 73.885714 | H13: 0.97142857 | I13: Très forte
A14: Université Paris Nanterre - Ville-d'Avray | B14: Autre formation | C14: C.M.I - Cursus Master en Ingénierie - Sciences pour l'ingénieur - Cursus Master en Ingénierie (CMI) : Ingénierie pour l'Aéronautique, les Transports et l'Energétique | D14: 24 | E14: 1542 | F14: 23 | G14: 64.25 | H14: 0.95833333 | I14: Très forte
A15: Université Paris Nanterre - Ville-d'Avray | B15: Licence | C15: Licence - Sciences pour l'ingénieur | D15: 24 | E15: 1513 | F15: 24 | G15: 63.041667 | H15: 1 | I15: Très forte
A16: Université Paris Nanterre | B16: Licence L.AS | C16: Licence - Portail Santé et société - Santé et sciences humaines et sociales | D16: 35 | E16: 1839 | F16: 35 | G16: 52.542857 | H16: 1 | I16: Très forte
A17: Université Paris Nanterre | B17: Licence | C17: Licence - Information et communication | D17: 50 | E17: 2517 | F17: 49 | G17: 50.34 | H17: 0.98 | I17: Très forte
A18: Université Paris Nanterre | B18: Licence | C18: Licence - Science politique | D18: 130 | E18: 6508 | F18: 131 | G18: 50.061538 | H18: 1.0076923 | I18: Très forte
A19: Université Paris Nanterre | B19: Licence | C19: Licence - Portail Droit français - Droit étranger - Droit français - common law | D19: 25 | E19: 1243 | F19: 25 | G19: 49.72 | H19: 1 | I19: Très forte
A20: Université Paris Nanterre | B20: Licence | C20: Licence - Portail Santé et société - Santé et sciences humaines et sociales | D20: 35 | E20: 1482 | F20: 35 | G20: 42.342857 | H20: 1 | I20: Très forte
... A48: Université Paris Nanterre | B48: Licence | C48: Double licence - Langues, littératures et civilisations étrangères et régionales / Langues, littératures et civilisations étrangères et régionales - Double Licence mention Langues, littératures et civilisations étrangères et régionales (LLCER) [Anglais] - mention LLCER [Allemand] | D48: 10 | E48: 195 | F48: 9 | G48: 19.5 | H48: 0.9 | I48: Modérée
A49: Université Paris Nanterre | B49: Licence | C49: Licence - Mathématiques et informatique appliquées aux sciences humaines et sociales | D49: 70 | E49: 1342 | F49: 69 | G49: 19.171429 | H49: 0.98571429 | I49: Modérée | J49: ← ma formation (rang 41 sur 87)
A50: Université Paris Nanterre | B50: Licence | C50: Licence - Economie et gestion - Parcours international franco-espagnol Equateur | D50: 15 | E50: 271 | F50: 15 | G50: 18.066667 | H50: 1 | I50: Modérée
A51: Université Paris Nanterre | B51: Licence | C51: Licence - Sciences de l'éducation et de la formation - Parcours Accompagnement socio-éducatif et formation | D51: 90 | E51: 1602 | F51: 87 | G51: 17.8 | H51: 0.96666667 | I51: Modérée
A52: Université Paris Nanterre | B52: Licence | C52: Licence - Humanités - Parcours Humanités et danse - Entièrement en distanciel | D52: 15 | E52: 254 | F52: 16 | G52: 16.933333 | H52: 1.0666667 | I52: Modérée
A53: Université Paris Nanterre | B53: Licence | C53: Licence - Droit | D53: 778 | E53: 13114 | F53: 778 | G53: 16.856041 | H53: 1 | I53: Modérée
A54: Université Paris Nanterre | B54: Licence | C54: Licence - Economie et gestion - Parcours international franco-espagnol | D54: 30 | E54: 499 | F54: 30 | G54: 16.633333 | H54: 1 | I54: Modérée
A55: Université Paris Nanterre | B55: Licence | C55: Licence - Histoire | D55: 92 | E55: 1518 | F55: 90 | G55: 16.5 | H55: 0.97826087 | I55: Modérée
A56: Université Paris Nanterre | B56: Licence | C56: Licence - Sociologie | D56: 170 | E56: 2804 | F56: 168 | G56: 16.494118 | H56: 0.98823529 | I56: Modérée
A57: Université Paris Nanterre | B57: Licence | C57: Licence - Portail Sciences et Techniques des Activités Physiques et Sportives | D57: 390 | E57: 6233 | F57: 389 | G57: 15.982051 | H57: 0.9974359 | I57: Modérée
A58: Université Paris Nanterre | B58: Licence | C58: Licence - Droit français - Droit étranger - Parcours Droit français - droit italien | D58: 35 | E58: 526 | F58: 35 | G58: 15.028571 | H58: 1 | I58: Modérée
A59: Université Paris Nanterre | B59: Licence | C59: Licence - Histoire de l'art et archéologie - Entièrement en distanciel | D59: 80 | E59: 1176 | F59: 79 | G59: 14.7 | H59: 0.9875 | I59: Modérée
A60: Université Paris Nanterre | B60: Licence | C60: Double licence - Histoire / Langues, littératures et civilisations étrangères et régionales - Double licence mention Histoire - mention Langues, littératures et civilisations étrangères et régionales [Anglais] | D60: 30 | E60: 432 | F60: 29 | G60: 14.4 | H60: 0.96666667 | I60: Modérée
A61: Université Paris Nanterre | B61: Licence | C61: Double licence - Langues, littératures et civilisations étrangères et régionales / Langues, littératures et civilisations étrangères et régionales - Double Licence mention Langues, littératures et civilisations étrangères et régionales (LLCER) [Espagnol] - mention LLCER [Portugais] | D61: 10 | E61: 143 | F61: 10 | G61: 14.3 | H61: 1 | I61: Modérée
... A95: Université Paris Nanterre | B95: Licence | C95: Licence - Langues étrangères appliquées - Parcours Grec - Anglais | D95: 15 | E95: 55 | F95: 15 | G95: 3.6666667 | H95: 1 | I95: Faible
